Workbook

Sheet Summary
A1: PSO system data comparison – PROD / ACC (UAT) / STG / TST
A2: Source: DsSystemData exports (sys files), one per environment. Generated 28 Sep 2026.
A4: Scope
A5: Compared: profile parameters, schedule exception types, groups and group permissions, organisation permissions, org-default list layouts, travel-time setup, profiles, terminology.
A6: Not compared: Users and System_Version (as requested), and all per-user tables. Per-user tables hold data tied to individual user accounts: each person’s saved filters, screen settings and list layouts, plus which groups, permissions and parameters are assigned to each user. They are left out because the set of users differs between environments, so comparing them would mostly show noise. This also means group membership (who is in which group) is not compared, only what each group is allowed to do.
A7: List, entry and polygon IDs are GUIDs that differ per environment, so lists are matched on content and travel polygons are summarised by count.
A8: ST_Ops_Mgr / ST_Ops_MGR are treated as the same group (case differs by environment); the Groups tab flags the spelling difference.
A9: AST environment: not available (credentials failed), so not included.
A10: Routing API key values are masked as [API key set]; the key value is identical everywhere it is set.
A11: Parameter definitions come from the project knowledge base; ones marked [Inferred] rest only on the parameter name and general PSO knowledge, so treat them as unverified.
A12: Legend: amber cell = differs from PROD; “DIFF” = not identical across all four; ␣ marks a leading/trailing space in a value; permissions show allow / allow_edit (T/F).
A14: Rows that differ from PROD | B14: Rows compared | C14: ACC (UAT) | D14: STG | E14: TST
A15: Parameters | B15: =ROWS(Parameters!$D$2:$D$50) -> 49 | C15: =SUMPRODUCT(--NOT(EXACT(Parameters!$E$2:$E$50,Parameters!$D$2:$D$50))) -> 21 | D15: =SUMPRODUCT(--NOT(EXACT(Parameters!$F$2:$F$50,Parameters!$D$2:$D$50))) -> 11 | E15: =SUMPRODUCT(--NOT(EXACT(Parameters!$G$2:$G$50,Parameters!$D$2:$D$50))) -> 28
A16: Exception Types | B16: =ROWS('Exception Types'!$D$2:$D$112) -> 111 | C16: =SUMPRODUCT(--NOT(EXACT('Exception Types'!$E$2:$E$112,'Exception Types'!$D$2:$D$112))) -> 6 | D16: =SUMPRODUCT(--NOT(EXACT('Exception Types'!$F$2:$F$112,'Exception Types'!$D$2:$D$112))) -> 10 | E16: =SUMPRODUCT(--NOT(EXACT('Exception Types'!$G$2:$G$112,'Exception Types'!$D$2:$D$112))) -> 46
A17: Group Permissions | B17: =ROWS('Group Permissions'!$D$2:$D$479) -> 478 | C17: =SUMPRODUCT(--NOT(EXACT('Group Permissions'!$E$2:$E$479,'Group Permissions'!$D$2:$D$479))) -> 137 | D17: =SUMPRODUCT(--NOT(EXACT('Group Permissions'!$F$2:$F$479,'Group Permissions'!$D$2:$D$479))) -> 229 | E17: =SUMPRODUCT(--NOT(EXACT('Group Permissions'!$G$2:$G$479,'Group Permissions'!$D$2:$D$479))) -> 228
A18: Groups | B18: =ROWS(Groups!$D$2:$D$77) -> 76 | C18: =SUMPRODUCT(--NOT(EXACT(Groups!$E$2:$E$77,Groups!$D$2:$D$77))) -> 29 | D18: =SUMPRODUCT(--NOT(EXACT(Groups!$F$2:$F$77,Groups!$D$2:$D$77))) -> 32 | E18: =SUMPRODUCT(--NOT(EXACT(Groups!$G$2:$G$77,Groups!$D$2:$D$77))) -> 26
A19: Org Permissions | B19: =ROWS('Org Permissions'!$D$2:$D$13) -> 12 | C19: =SUMPRODUCT(--NOT(EXACT('Org Permissions'!$E$2:$E$13,'Org Permissions'!$D$2:$D$13))) -> 2 | D19: =SUMPRODUCT(--NOT(EXACT('Org Permissions'!$F$2:$F$13,'Org Permissions'!$D$2:$D$13))) -> 3 | E19: =SUMPRODUCT(--NOT(EXACT('Org Permissions'!$G$2:$G$13,'Org Permissions'!$D$2:$D$13))) -> 6
A20: Lists | B20: =ROWS(Lists!$D$2:$D$83) -> 82 | C20: =SUMPRODUCT(--NOT(EXACT(Lists!$E$2:$E$83,Lists!$D$2:$D$83))) -> 10 | D20: =SUMPRODUCT(--NOT(EXACT(Lists!$F$2:$F$83,Lists!$D$2:$D$83))) -> 7 | E20: =SUMPRODUCT(--NOT(EXACT(Lists!$G$2:$G$83,Lists!$D$2:$D$83))) -> 38
A21: Travel | B21: =ROWS(Travel!$D$2:$D$18) -> 17 | C21: =SUMPRODUCT(--NOT(EXACT(Travel!$E$2:$E$18,Travel!$D$2:$D$18))) -> 12 | D21: =SUMPRODUCT(--NOT(EXACT(Travel!$F$2:$F$18,Travel!$D$2:$D$18))) -> 7 | E21: =SUMPRODUCT(--NOT(EXACT(Travel!$G$2:$G$18,Travel!$D$2:$D$18))) -> 14
A22: Profiles & Other | B22: =ROWS('Profiles & Other'!$D$2:$D$13) -> 12 | C22: =SUMPRODUCT(--NOT(EXACT('Profiles & Other'!$E$2:$E$13,'Profiles & Other'!$D$2:$D$13))) -> 1 | D22: =SUMPRODUCT(--NOT(EXACT('Profiles & Other'!$F$2:$F$13,'Profiles & Other'!$D$2:$D$13))) -> 2 | E22: =SUMPRODUCT(--NOT(EXACT('Profiles & Other'!$G$2:$G$13,'Profiles & Other'!$D$2:$D$13))) -> 3
A23: Total | B23: =SUM(B15:B22) -> 837 | C23: =SUM(C15:C22) -> 218 | D23: =SUM(D15:D22) -> 301 | E23: =SUM(E15:E22) -> 389
A24: Share of rows differing from PROD | C24: =IF($B23=0,0,C23/$B23) -> 0.260454 | D24: =IF($B23=0,0,D23/$B23) -> 0.35961768 | E24: =IF($B23=0,0,E23/$B23) -> 0.46475508
A25: Rows not identical across all four | B25: =COUNTIF(Parameters!$H$2:$H$50,"DIFF")+COUNTIF('Exception Types'!$H$2:$H$112,"DIFF")+COUNTIF('Group Permissions'!$H$2:$H$479,"DIFF")+COUNTIF(Groups!$H$2:$H$77,"DIFF")+COUNTIF('Org Permissions'!$H$2:$H$13,"DIFF")+COUNTIF(Lists!$H$2:$H$83,"DIFF")+COUNTIF(Travel!$H$2:$H$18,"DIFF")+COUNTIF('Profiles & Other'!$H$2:$H$13,"DIFF") -> 488
A26: PSO version | B26: =Versions!A3 -> All 4 environments are on PSO 6.16.0.41
A28: Key findings
A29: Travel: committed activities | B29: CommittedActivitiesProfile is set to RealTimeTravel (TomTom) in PROD and STG, and to HierarchicalTravelMatrix in ACC and TST. But the profile is only used if DEFAULT.CommittedActivitiesProfileId points at it (a required setup step). That is set in ACC and STG and empty in PROD and TST. So STG is the only environment where real-time travel is fully wired; in PROD the profile exists but DEFAULT does not reference it. Verify: dataset-level parameter overrides are not part of this export and could change that.
A30: Travel: default calculation | B30: TST uses StraightLine on DEFAULT; PROD, ACC and STG use HierarchicalTravelMatrix. RealTimeTravelProvider=NONE is set on DEFAULT in PROD and STG only.
A31: Travel-time weighting | B31: Only ACC has a full travel-time weighting set (“Default”, America/Regina, 343 polygons, weightings 0.12–2.84). PROD has two Lucky Lake polygons (0.5 each) under DEFAULT plus a “TEST” profile; ACC has none of the Lucky Lake polygons; STG and TST have no travel-time data at all. TST references TravelTimeProfileId values (DEFAULT, STRAIGHTLINE) that do not exist in its own file. ID casing also differs (“Default” in ACC, “DEFAULT” in PROD/TST).
A32: AllowSplitTravel | B32: Set (True) only in PROD; absent in ACC, STG and TST. Not documented in the KB, and the KB says implicit-break travel splitting follows split_allowed on the destination activity type with no separate toggle, so this parameter is worth raising with IFS.
A33: Committed / shift behaviour | B33: CommitToAllocatedShift is False in PROD and STG, True in ACC and TST. ImplicitBreaksOnOffEventsRequired: True in PROD, False in TST, absent in ACC/STG. SortValuePrecedenceMaximumStatus=40 in PROD and STG only.
A34: Exception types | B34: TST has 35 CommittedActivitiesProfile rows and has 110/130/250/280 active in DEFAULT (inactive elsewhere). STG has five DEFAULT types (2000, 2001, 2005, 2500, 3001) and CONTRACTORS 450 that exist nowhere else; the DEFAULT ones are described “Test”, “test 1”, “Test Case”, “Test Case 25” and “test123”, so they look like leftover test data. ACC has an active type 1002 described “nonsense” (TST has it inactive; PROD and STG don’t have it). DEFAULT type 1000 exists only in TST. Type 90 attention is 10 in PROD/STG and 2 in ACC/TST.
A35: Admin groups | B35: PROD uses SAST_SYSTEM_ADMIN (24 permissions). ACC/STG/TST use GOGH_ADMIN_PERMISSION (no direct permissions, inherits FNDSCH_ADMIN); ACC and STG also have GOGHSUPERUSER; ACC alone has REG; TST alone has an unnamed GUID group.
A36: Group naming | B36: ST_Ops_Mgr in PROD/ACC but ST_Ops_MGR in STG/TST. STG group descriptions say “Sasktel” instead of “SaskTel”.
A37: Role permissions | B37: Most group permission rows are explicit DENIES (241 of 341 in PROD), so row counts (e.g. ST_Planner 78 / 91 / 33 / 34) mostly measure how many deny rows an environment carries, not what a role can do. Effectively ALLOWED permissions are close: ST_Planner 13 / 11 / 10 / 13, ST_Scheduler 8 / 6 / 7 / 8, ST_Dispatch 9 / 7 / 9 / 11, ST_WFM_MGR 10 / 14 / 5 / 7 (PROD / ACC / STG / TST). Real differences: ManualChanges is allowed for Planner, Scheduler and Dispatch in STG/TST (Dispatch also in ACC) but not in PROD, where only ST_WFM_MGR has it; ACC ST_WFM_MGR is allowed Administrator, AdministrationWorkspace and AdminTravelProfilesView, which PROD ST_WFM_MGR is not; ViewAllDatasets is allowed for every ST_ role in PROD but denied for some roles in STG/TST. A permission with no row falls back to its default (not visible in the sys file), so confirm in the Workbench.
A38: NORTH / SOUTH | B38: Child groups of Administrator in ACC, STG and TST; no parent in PROD. Their permission rows (0 in PROD, 1 in ACC, 8 / 7 in STG and TST) are all explicit denies, so none of them grants anything directly.
A39: Org permissions | B39: ViewAllDatasets: allowed in PROD and STG, denied in ACC. STG alone allows AdministrationWorkspace and DataCaptureView at org level; TST adds Administrator and three Gateway auth denials.
A40: Lists and clean-up | B40: Org-default column layouts differ (lists 101 and 11 differ in all four). PROD’s Entry table contains junk labels from testing (e.g. dcvdc, edefd, efef). ACC has trailing spaces in ResourceLabel/ResourceText/ResourceSubtext; TST has one in ResourceLabel.
... A42: Closest to PROD | B42: By total rows, ACC is closest to PROD (about 26% of rows differ), then STG (about 36%), then TST (about 46%). Read the permission part with care: those row counts are inflated by explicit deny rows. On parameters STG is closest (11 rows differ, vs 21 for ACC and 28 for TST) because it shares PROD’s CommitToAllocatedShift, SortValuePrecedenceMaximumStatus, RealTimeTravelProvider and committed-profile travel option. See the counts table above.
A44: Tabs
A45: Versions | B45: Current PSO version, last upgrade and last patch per environment, with a red/green banner if they are not all on the same version.
...

Sheet Versions
A1: PSO version by environment
A2: From the System_Version table; all times UTC. Current version = highest version recorded. Last upgrade = most recent "Upgrade from" record. Last patch = most recent "Update" record.
A3: =IF(COUNTA(B6:B9)<2,"Not enough data to compare",IF(COUNTIF(D6:D9,"BEHIND")=0,"All "&COUNTA(B6:B9)&" environments are on PSO "&INDEX(B6:B9,MATCH(MAX(Q6:Q9),Q6:Q9,0)),"VERSION MISMATCH - the environments are NOT all on the same PSO version")) -> All 4 environments are on PSO 6.16.0.41
A4: =IF(COUNTIF(D6:D9,"BEHIND")=0,"",IF(COUNTIF(C6:C9,C6)<COUNTA(C6:C9),"Different RELEASES across environments","Same release ("&C6&"), different patch builds"))
A5: Environment | B5: Current version | C5: Release | D5: Status | E5: Last upgrade (UTC) | F5: Upgraded from | G5: Upgraded to | H5: Last patch version | I5: Last patch (UTC) | J5: Days since upgrade | K5: Created (UTC) | M5: major | N5: minor | O5: patch | P5: build | Q5: sort key
A6: PROD | B6: 6.16.0.41 | C6: =M6&"."&N6 -> 6.16 | D6: =IF(B6="","UNKNOWN",IF(Q6=MAX($Q$6:$Q$9),"LATEST","BEHIND")) -> LATEST | E6: 46145.908 | F6: 6.15.0 | G6: 6.16.0 | H6: 6.16.0.41 | I6: 46145.908 | J6: =IF(E6="","",INT(TODAY()-E6)) -> 149 | K6: 44858.685 | M6: =IFERROR(VALUE(TRIM(MID(SUBSTITUTE($B6,".",REPT(" ",20)),1,20))),0) -> 6 | N6: =IFERROR(VALUE(TRIM(MID(SUBSTITUTE($B6,".",REPT(" ",20)),21,20))),0) -> 16 | O6: =IFERROR(VALUE(TRIM(MID(SUBSTITUTE($B6,".",REPT(" ",20)),41,20))),0) -> 0 | P6: =IFERROR(VALUE(TRIM(MID(SUBSTITUTE($B6,".",REPT(" ",20)),61,20))),0) -> 41 | Q6: =M6*1000000000+N6*1000000+O6*1000+P6 -> 6016000041
A7: ACC (UAT) | B7: 6.16.0.41 | C7: =M7&"."&N7 -> 6.16 | D7: =IF(B7="","UNKNOWN",IF(Q7=MAX($Q$6:$Q$9),"LATEST","BEHIND")) -> LATEST | E7: 46056.127 | F7: 6.15.0 | G7: 6.16.0 | H7: 6.16.0.41 | I7: 46056.127 | J7: =IF(E7="","",INT(TODAY()-E7)) -> 238 | K7: 44858.685 | M7: =IFERROR(VALUE(TRIM(MID(SUBSTITUTE($B7,".",REPT(" ",20)),1,20))),0) -> 6 | N7: =IFERROR(VALUE(TRIM(MID(SUBSTITUTE($B7,".",REPT(" ",20)),21,20))),0) -> 16 | O7: =IFERROR(VALUE(TRIM(MID(SUBSTITUTE($B7,".",REPT(" ",20)),41,20))),0) -> 0 | P7: =IFERROR(VALUE(TRIM(MID(SUBSTITUTE($B7,".",REPT(" ",20)),61,20))),0) -> 41 | Q7: =M7*1000000000+N7*1000000+O7*1000+P7 -> 6016000041
A8: STG | B8: 6.16.0.41 | C8: =M8&"."&N8 -> 6.16 | D8: =IF(B8="","UNKNOWN",IF(Q8=MAX($Q$6:$Q$9),"LATEST","BEHIND")) -> LATEST | E8: 46060.822 | F8: 6.15.0 | G8: 6.16.0 | H8: 6.16.0.41 | I8: 46060.822 | J8: =IF(E8="","",INT(TODAY()-E8)) -> 234 | K8: 44858.685 | M8: =IFERROR(VALUE(TRIM(MID(SUBSTITUTE($B8,".",REPT(" ",20)),1,20))),0) -> 6 | N8: =IFERROR(VALUE(TRIM(MID(SUBSTITUTE($B8,".",REPT(" ",20)),21,20))),0) -> 16 | O8: =IFERROR(VALUE(TRIM(MID(SUBSTITUTE($B8,".",REPT(" ",20)),41,20))),0) -> 0 | P8: =IFERROR(VALUE(TRIM(MID(SUBSTITUTE($B8,".",REPT(" ",20)),61,20))),0) -> 41 | Q8: =M8*1000000000+N8*1000000+O8*1000+P8 -> 6016000041
A9: TST | B9: 6.16.0.41 | C9: =M9&"."&N9 -> 6.16 | D9: =IF(B9="","UNKNOWN",IF(Q9=MAX($Q$6:$Q$9),"LATEST","BEHIND")) -> LATEST | E9: 45947.022 | F9: 6.15.0 | G9: 6.16.0 | H9: 6.16.0.41 | I9: 45965.109 | J9: =IF(E9="","",INT(TODAY()-E9)) -> 347 | K9: 44858.685 | M9: =IFERROR(VALUE(TRIM(MID(SUBSTITUTE($B9,".",REPT(" ",20)),1,20))),0) -> 6 | N9: =IFERROR(VALUE(TRIM(MID(SUBSTITUTE($B9,".",REPT(" ",20)),21,20))),0) -> 16 | O9: =IFERROR(VALUE(TRIM(MID(SUBSTITUTE($B9,".",REPT(" ",20)),41,20))),0) -> 0 | P9: =IFERROR(VALUE(TRIM(MID(SUBSTITUTE($B9,".",REPT(" ",20)),61,20))),0) -> 41 | Q9: =M9*1000000000+N9*1000000+O9*1000+P9 -> 6016000041
A11: Status compares each environment with the highest version in the table (numeric comparison, so 6.13.0.9 is older than 6.13.0.67).
A12: The vendor-stamped SYSTEM_USER patch records carry the same timestamp in every environment, so they say nothing about when an environment was upgraded; they are ignored for the upgrade and patch dates.
A13: "Days since upgrade" is live (TODAY) and will change each time the workbook is opened. Columns M:Q are helper columns for the Status formula.

Sheet Parameters
A1: Profile | B1: Parameter | C1: App type | D1: PROD | E1: ACC (UAT) | F1: STG | G1: TST | H1: Status | I1: What it does (plain English)
A2: DEFAULT | B2: ARPResourceLabelFormat | C2: PSW | D2: (absent) | E2: (absent) | F2: (absent) | G2: {first_name|surname|id} | H2: =IF(AND(EXACT(D2,E2),EXACT(E2,F2),EXACT(F2,G2)),"Same","DIFF") -> DIFF | I2: [Inferred] How a resource is labelled in the Advanced Resource Planner (ARP).
A3: DEFAULT | B3: ActivityBaseLabel | C3: PSW | D3: (absent) | E3: {id} | F3: ␣{Activity.id} | G3: {id} | H3: =IF(AND(EXACT(D3,E3),EXACT(E3,F3),EXACT(F3,G3)),"Same","DIFF") -> DIFF | I3: [Inferred] Label format for activities, apparently the base/default label the other activity label settings build on. Confirm on the Parameters screen.
A4: DEFAULT | B4: ActivityLabel | C4: SWB | D4: {Activity.Additional_Attribute.Non-Availability Type} {Activity.Additional_Attribute.Task Type} | {Activity.Additional_Attribute.Call ID} |WT:{Activity.Additional_Attribute.Work Task ID} | Act: {Activity.#label} | E4: {Activity.Additional_Attribute.Non-Availability Type} {Activity.Additional_Attribute.Task Type} | {Activity.Additional_Attribute.Call ID} |WT:{Activity.Additional_Attribute.Work Task ID} | Act: {Activity.#label} | F4: {Activity.Additional_Attribute.Non-Availability Type} {Activity.Additional_Attribute.Task Type} | {Activity.Additional_Attribute.Call ID} |WT:{Activity.Additional_Attribute.Work Task ID} | Act: {Activity.#label} | G4: {Activity.Additional_Attribute.Non-Availability Type} {Activity.Additional_Attribute.Task Type} | {Activity.Additional_Attribute.Call ID} |WT:{Activity.Additional_Attribute.Work Task ID} | Act: {Activity.#label} | H4: =IF(AND(EXACT(D4,E4),EXACT(E4,F4),EXACT(F4,G4)),"Same","DIFF") -> Same
A5: DEFAULT | B5: ActivitySubtext | C5: SWB | D5: {#status} | Priority: {Activity.priority} | E5: {#status} Priority: {Activity.priority} | F5: {#status} | Priority: {Activity.priority} | G5: {#status} | Priority: {Activity.priority} | H5: =IF(AND(EXACT(D5,E5),EXACT(E5,F5),EXACT(F5,G5)),"Same","DIFF") -> DIFF | I5: [Inferred] Secondary line of text shown under the main activity text. Same {Table.Field} expression syntax.
A6: DEFAULT | B6: ActivityText | C6: SWB | D6: (absent) | E6: (absent) | F6: (absent) | G6: {#label} | H6: =IF(AND(EXACT(D6,E6),EXACT(E6,F6),EXACT(F6,G6)),"Same","DIFF") -> DIFF | I6: Text shown on each activity bar on the Gantt. Built from an expression such as {Table.Field}; fields starting with # are derived values.
A7: DEFAULT | B7: AllowAllocateBeforeCommitted | C7: DSE | D7: True | E7: True | F7: True | G7: True | H7: =IF(AND(EXACT(D7,E7),EXACT(E7,F7),EXACT(F7,G7)),"Same","DIFF") -> Same
A8: DEFAULT | B8: AllowAuthenticationGateway | C8: ALL | D8: True | E8: True | F8: True | G8: True | H8: =IF(AND(EXACT(D8,E8),EXACT(E8,F8),EXACT(F8,G8)),"Same","DIFF") -> Same
A9: DEFAULT | B9: AllowLocationlessActivities | C9: ALL | D9: True | E9: True | F9: True | G9: True | H9: =IF(AND(EXACT(D9,E9),EXACT(E9,F9),EXACT(F9,G9)),"Same","DIFF") -> Same
A10: DEFAULT | B10: AllowSplitTravel | C10: DSE | D10: True | E10: (absent) | F10: (absent) | G10: (absent) | H10: =IF(AND(EXACT(D10,E10),EXACT(E10,F10),EXACT(F10,G10)),"Same","DIFF") -> DIFF | I10: [Inferred] By name, lets the scheduler split a travel leg (for example around a break or a shift boundary). NOT documented in the KB, and the KB currently says there is no separate travel-splitting toggle (it follows split_allowed on the destination activity type), so this needs confirming with IFS. Present only in PROD.
A11: DEFAULT | B11: CascadeSchedulingObjectDeletions | C11: SIM | D11: False | E11: False | F11: False | G11: False | H11: =IF(AND(EXACT(D11,E11),EXACT(E11,F11),EXACT(F11,G11)),"Same","DIFF") -> Same
A12: DEFAULT | B12: CommitToAllocatedShift | C12: SWB | D12: False | E12: True | F12: False | G12: True | H12: =IF(AND(EXACT(D12,E12),EXACT(E12,F12),EXACT(F12,G12)),"Same","DIFF") -> DIFF | I12: When someone manually commits an activity, keep it in the shift it is already allocated to. If it is on together with CommitToAvailabilityWindow, whichever has the later start wins.
A13: DEFAULT | B13: CommittedActivitiesConstraintsOption | C13: DSE | D13: (absent) | E13: 1 | F13: 1 | G13: 1 | H13: =IF(AND(EXACT(D13,E13),EXACT(E13,F13),EXACT(F13,G13)),"Same","DIFF") -> DIFF | I13: 1 = committed activities (status 30–40) have their time constraints obeyed, so the start may be pushed to a valid time; 0 = constraints are not enforced. Field reality: only Activity_Availabilities are enforced, not SLA windows. No effect once the resource is Travelling (50).
A14: DEFAULT | B14: CommittedActivitiesProfileId | C14: DSE | D14: (null) | E14: CommittedActivitiesProfile | F14: CommittedActivitiesProfile | G14: (null) | H14: =IF(AND(EXACT(D14,E14),EXACT(E14,F14),EXACT(F14,G14)),"Same","DIFF") -> DIFF | I14: Points the DEFAULT profile at the profile to use for committed (imminent) activities. This is step 2 of the real-time travel setup; without it the committed-activities profile is not picked up.
A15: DEFAULT | B15: GpsFrequency | C15: DSE | D15: (absent) | E15: PT5M | F15: (absent) | G15: (absent) | H15: =IF(AND(EXACT(D15,E15),EXACT(E15,F15),EXACT(F15,G15)),"Same","DIFF") -> DIFF | I15: [Inferred] By name, how often GPS positions are expected or used (PT5M = every 5 minutes). Set only in ACC.
A16: DEFAULT | B16: HierarchicalDatabaseMatrixId | C16: ALL | D16: NA | E16: NA | F16: NA | G16: (null) | H16: =IF(AND(EXACT(D16,E16),EXACT(E16,F16),EXACT(F16,G16)),"Same","DIFF") -> DIFF | I16: Which HTM (travel matrix) to use. Set per profile, this is how multiple HTM connections are supported.
A17: DEFAULT | B17: ImplicitBreaksOnOffEventsRequired | C17: DSE | D17: True | E17: (absent) | F17: (absent) | G17: False | H17: =IF(AND(EXACT(D17,E17),EXACT(E17,F17),EXACT(F17,G17)),"Same","DIFF") -> DIFF | I17: Controls when PSO assumes an implicit break has been taken: whether it waits for the resource’s break on/off events or assumes the break happens as planned. Added in 6.5.0.25; a fix in 6.16.0.79 made it apply during appointment booking. The True/False meaning is inferred from the name.
A18: DEFAULT | B18: IsochroneCompareStraight | C18: PSW | D18: (absent) | E18: False | F18: False | G18: False | H18: =IF(AND(EXACT(D18,E18),EXACT(E18,F18),EXACT(F18,G18)),"Same","DIFF") -> DIFF | I18: Used with the Travel Analyser isochrone preview to compare against a straight-line disc when the preview looks very different from the real isochrone.
A19: DEFAULT | B19: JsonFormatVersion | C19: SBM | D19: 1 | E19: 1 | F19: 1 | G19: 1 | H19: =IF(AND(EXACT(D19,E19),EXACT(E19,F19),EXACT(F19,G19)),"Same","DIFF") -> Same
A20: DEFAULT | B20: JsonFormatVersion | C20: SRG | D20: 1 | E20: 1 | F20: 1 | G20: 1 | H20: =IF(AND(EXACT(D20,E20),EXACT(E20,F20),EXACT(F20,G20)),"Same","DIFF") -> Same
A21: DEFAULT | B21: MaxDisplaceableActivityPriority | C21: ABE | D21: (absent) | E21: -1 | F21: -1 | G21: -1 | H21: =IF(AND(EXACT(D21,E21),EXACT(E21,F21),EXACT(F21,G21)),"Same","DIFF") -> DIFF | I21: Appointment booking: low-priority activities up to this priority are ignored when building an offer (no attempt to reallocate them). -1 = off; e.g. 2 ignores priority 1–2. Never applies to committed-or-later or fully fixed activities.
A22: DEFAULT | B22: MaxUserSessions | C22: ALL | D22: -1 | E22: -1 | F22: -1 | G22: (absent) | H22: =IF(AND(EXACT(D22,E22),EXACT(E22,F22),EXACT(F22,G22)),"Same","DIFF") -> DIFF | I22: [Inferred] By name, the cap on concurrent sessions per user; -1 presumably means unlimited.
A23: DEFAULT | B23: NoActivityChangesFromStatus | C23: SWB | D23: 32 | E23: 32 | F23: 32 | G23: 32 | H23: =IF(AND(EXACT(D23,E23),EXACT(E23,F23),EXACT(F23,G23)),"Same","DIFF") -> Same
A24: DEFAULT | B24: NoStatusChangesFromStatus | C24: SWB | D24: 32 | E24: 32 | F24: 32 | G24: 32 | H24: =IF(AND(EXACT(D24,E24),EXACT(E24,F24),EXACT(F24,G24)),"Same","DIFF") -> Same
A25: DEFAULT | B25: OpenIdAllowLegacyAuthentication | C25: GWY | D25: True | E25: True | F25: True | G25: True | H25: =IF(AND(EXACT(D25,E25),EXACT(E25,F25),EXACT(F25,G25)),"Same","DIFF") -> Same
A26: DEFAULT | B26: OpenIdAuthority | C26: ALL | D26: https://sast.ifs.cloud/auth/realms/sateprd1 | E26: https://sast-uat.ifs.cloud/auth/realms/sateuat1 | F26: https://sast-stg.ifs.cloud/auth/realms/satestg1 | G26: https://paq3uqy-del1.build.ifs.cloud/auth/realms/paq3uqydel1 | H26: =IF(AND(EXACT(D26,E26),EXACT(E26,F26),EXACT(F26,G26)),"Same","DIFF") -> DIFF | I26: Issuer URL of the identity provider used for single sign-on (OpenID Connect). Expected to differ per environment. If it is wrong, logins fail; the packaged “Reset OpenIdAuthority.xml” restores password login.
A27: DEFAULT | B27: OpenIdClientId | C27: ALL | D27: IFS_automation | E27: IFS_automation | F27: IFS_automation | G27: IFS_automation | H27: =IF(AND(EXACT(D27,E27),EXACT(E27,F27),EXACT(F27,G27)),"Same","DIFF") -> Same
A28: DEFAULT | B28: PrivateActivityLabel | C28: SWB | D28: (absent) | E28: (absent) | F28: (absent) | G28: {Activity.description} | H28: =IF(AND(EXACT(D28,E28),EXACT(E28,F28),EXACT(F28,G28)),"Same","DIFF") -> DIFF | I28: [Inferred] Label shown for private activities outside the Gantt, by analogy with ActivityLabel.
A29: DEFAULT | B29: PrivateActivityText | C29: SWB | D29: (absent) | E29: (absent) | F29: (absent) | G29: {Activity.description} | H29: =IF(AND(EXACT(D29,E29),EXACT(E29,F29),EXACT(F29,G29)),"Same","DIFF") -> DIFF | I29: [Inferred] Text shown on private activities (unavailability blocks such as holiday, sickness, training) on the Gantt.
A30: DEFAULT | B30: RealTimeTravelProvider | C30: ALL | D30: NONE | E30: (absent) | F30: NONE | G30: (absent) | H30: =IF(AND(EXACT(D30,E30),EXACT(E30,F30),EXACT(F30,G30)),"Same","DIFF") -> DIFF | I30: Which online routing service supplies real-time travel: NONE or TOMTOM.
A31: DEFAULT | B31: ResourceDescriptionFormat | C31: ARC | D31: (absent) | E31: (absent) | F31: (absent) | G31: {Resources.first_name} {Resources.surname} [{Additional Attribute.Employer}] | H31: =IF(AND(EXACT(D31,E31),EXACT(E31,F31),EXACT(F31,G31)),"Same","DIFF") -> DIFF | I31: [Inferred] Format of the resource’s description string, e.g. in lists and tooltips.
A32: DEFAULT | B32: ResourceLabel | C32: SWB | D32: {first_name} {surname} [{Additional_Attribute.Employer}] | E32: {first_name} {surname} [{Additional_Attribute.Employer}]␣ | F32: {first_name} {surname} [{Additional_Attribute.Employer}] | G32: {first_name} {surname} [{Additional_Attribute.Employer}]␣ | H32: =IF(AND(EXACT(D32,E32),EXACT(E32,F32),EXACT(F32,G32)),"Same","DIFF") -> DIFF | I32: How a resource is named outside the Gantt, e.g. {First name} {Surname} [{Id}] shows “Charles Ollivon [T1001]”. Anything outside { } (spaces, brackets) is shown as typed, so a trailing space is cosmetic only.
A33: DEFAULT | B33: ResourceSubtext | C33: SWB | D33: {Additional_Attribute.Employer} | E33: {Additional_Attribute.Employer}␣ | F33: {Additional_Attribute.Employer} | G33: {Additional_Attribute.Employer} | H33: =IF(AND(EXACT(D33,E33),EXACT(E33,F33),EXACT(F33,G33)),"Same","DIFF") -> DIFF | I33: [Inferred] Secondary line shown under the resource name (here the employer).
A34: DEFAULT | B34: ResourceText | C34: SWB | D34: {first_name} {surname} | E34: {first_name} {surname}␣ | F34: {first_name} {surname} | G34: {first_name} {surname} | H34: =IF(AND(EXACT(D34,E34),EXACT(E34,F34),EXACT(F34,G34)),"Same","DIFF") -> DIFF | I34: [Inferred] Main text shown for each resource row on the Gantt, by analogy with ActivityText.
A35: DEFAULT | B35: RoutingApiKey | C35: ALL | D35: (absent) | E35: (absent) | F35: [API key set] | G35: [API key set] | H35: =IF(AND(EXACT(D35,E35),EXACT(E35,F35),EXACT(F35,G35)),"Same","DIFF") -> DIFF | I35: API key for the online routing service; required for real-time travel. (Masked in this workbook.)
A36: DEFAULT | B36: SLAActivityAgeingFactor | C36: SWB | D36: (absent) | E36: (absent) | F36: 3 | G36: 1 | H36: =IF(AND(EXACT(D36,E36),EXACT(E36,F36),EXACT(F36,G36)),"Same","DIFF") -> DIFF | I36: [Inferred] By name, a multiplier on how SLA-related activity age is calculated or displayed. Confirm before relying on it.
A37: DEFAULT | B37: SchedulingWindowLength | C37: DSE | D37: (absent) | E37: (absent) | F37: (absent) | G37: P2D | H37: =IF(AND(EXACT(D37,E37),EXACT(E37,F37),EXACT(F37,G37)),"Same","DIFF") -> DIFF | I37: [Inferred] By name, how far ahead the scheduler plans (P2D = 2 days). Related to the dataset’s Scheduling Work Days, but the parameter itself is not documented in the KB.
A38: DEFAULT | B38: SortValuePrecedenceMaximumStatus | C38: ALL | D38: 40 | E38: (absent) | F38: 40 | G38: (absent) | H38: =IF(AND(EXACT(D38,E38),EXACT(E38,F38),EXACT(F38,G38)),"Same","DIFF") -> DIFF | I38: Order of committed activities. Default 30 sorts by status first (Accepted before Downloaded before Sent before Committed), then commit_sort_value. Setting 40 makes commit_sort_value the main key with status as tie-breaker. Each activity needs a unique status + sort value + date_time_status combination.
A39: DEFAULT | B39: StandardSendScheduleExceptionAccepts | C39: SWB | D39: (absent) | E39: False | F39: (absent) | G39: True | H39: =IF(AND(EXACT(D39,E39),EXACT(E39,F39),EXACT(F39,G39)),"Same","DIFF") -> DIFF | I39: When true, schedule-exception acknowledgements are handled in the standard way and the separate Schedule_Exception_Response broadcast is bypassed.
... A41: DEFAULT | B41: TravelTimeProfileId | C41: ALL | D41: (absent) | E41: Default | F41: (absent) | G41: DEFAULT | H41: =IF(AND(EXACT(D41,E41),EXACT(E41,F41),EXACT(F41,G41)),"Same","DIFF") -> DIFF | I41: Which travel-time profile (time-of-day and area weightings, barriers) adjusts journey times. It is the last fallback after Shift, Resource and Resource Type. The system ships with an empty DEFAULT profile.
...

Sheet Exception Types
A1: Profile | B1: Type ID | C1: Description | D1: PROD | E1: ACC (UAT) | F1: STG | G1: TST | H1: Status
A2: DEFAULT | B2: 10 | D2: on / attn 1 / act 600 | E2: on / attn 1 / act 600 | F2: on / attn 1 / act 600 | G2: on / attn 1 / act 600 | H2: =IF(AND(EXACT(D2,E2),EXACT(E2,F2),EXACT(F2,G2)),"Same","DIFF") -> Same
A3: DEFAULT | B3: 20 | D3: on / attn 10 / act 10 | E3: (absent) | F3: (absent) | G3: on / attn 10 / act 10 | H3: =IF(AND(EXACT(D3,E3),EXACT(E3,F3),EXACT(F3,G3)),"Same","DIFF") -> DIFF
A4: DEFAULT | B4: 30 | D4: off / attn 10 / act 10 | E4: off / attn 10 / act 10 | F4: off / attn 10 / act 10 | G4: off / attn 10 / act 10 | H4: =IF(AND(EXACT(D4,E4),EXACT(E4,F4),EXACT(F4,G4)),"Same","DIFF") -> Same
A5: DEFAULT | B5: 40 | D5: off / attn 50 / act - | E5: off / attn 50 / act - | F5: off / attn 50 / act - | G5: off / attn 50 / act - | H5: =IF(AND(EXACT(D5,E5),EXACT(E5,F5),EXACT(F5,G5)),"Same","DIFF") -> Same
A6: DEFAULT | B6: 50 | D6: on / attn 10 / act 0 | E6: on / attn 10 / act 0 | F6: on / attn 10 / act 0 | G6: on / attn 10 / act 0 | H6: =IF(AND(EXACT(D6,E6),EXACT(E6,F6),EXACT(F6,G6)),"Same","DIFF") -> Same
A7: DEFAULT | B7: 60 | D7: on / attn 10 / act 0 | E7: on / attn 10 / act 0 | F7: on / attn 10 / act 0 | G7: on / attn 10 / act 0 | H7: =IF(AND(EXACT(D7,E7),EXACT(E7,F7),EXACT(F7,G7)),"Same","DIFF") -> Same
A8: DEFAULT | B8: 70 | D8: on / attn 10 / act - | E8: on / attn 10 / act - | F8: on / attn 10 / act - | G8: on / attn 10 / act - | H8: =IF(AND(EXACT(D8,E8),EXACT(E8,F8),EXACT(F8,G8)),"Same","DIFF") -> Same
A9: DEFAULT | B9: 80 | D9: off / attn 1 / act - | E9: off / attn 1 / act - | F9: off / attn 1 / act - | G9: off / attn 1 / act - | H9: =IF(AND(EXACT(D9,E9),EXACT(E9,F9),EXACT(F9,G9)),"Same","DIFF") -> Same
A10: DEFAULT | B10: 90 | D10: off / attn 10 / act 600 | E10: off / attn 2 / act 600 | F10: off / attn 10 / act 600 | G10: off / attn 2 / act 600 | H10: =IF(AND(EXACT(D10,E10),EXACT(E10,F10),EXACT(F10,G10)),"Same","DIFF") -> DIFF
A11: DEFAULT | B11: 110 | D11: off / attn 10 / act 3600 | E11: off / attn 10 / act 3600 | F11: off / attn 10 / act 3600 | G11: on / attn 10 / act 3600 | H11: =IF(AND(EXACT(D11,E11),EXACT(E11,F11),EXACT(F11,G11)),"Same","DIFF") -> DIFF
A12: DEFAULT | B12: 120 | D12: on / attn 10 / act 600 | E12: (absent) | F12: (absent) | G12: on / attn 10 / act 600 | H12: =IF(AND(EXACT(D12,E12),EXACT(E12,F12),EXACT(F12,G12)),"Same","DIFF") -> DIFF
A13: DEFAULT | B13: 130 | D13: off / attn 10 / act - | E13: off / attn 10 / act - | F13: off / attn 10 / act - | G13: on / attn 10 / act 600 | H13: =IF(AND(EXACT(D13,E13),EXACT(E13,F13),EXACT(F13,G13)),"Same","DIFF") -> DIFF
... A38: DEFAULT | B38: 430 | D38: (absent) | E38: (absent) | F38: (absent) | G38: on / attn 1 / act - | H38: =IF(AND(EXACT(D38,E38),EXACT(E38,F38),EXACT(F38,G38)),"Same","DIFF") -> DIFF
A39: DEFAULT | B39: 1000 | C39: Tasks committed outside of a Shift | D39: (absent) | E39: (absent) | F39: (absent) | G39: on / attn 0 / act 1 | H39: =IF(AND(EXACT(D39,E39),EXACT(E39,F39),EXACT(F39,G39)),"Same","DIFF") -> DIFF
A40: DEFAULT | B40: 1001 | C40: Emergency Work | D40: on / attn 1 / act - | E40: on / attn 1 / act - | F40: on / attn 1 / act - | G40: on / attn 20 / act - | H40: =IF(AND(EXACT(D40,E40),EXACT(E40,F40),EXACT(F40,G40)),"Same","DIFF") -> DIFF
A41: DEFAULT | B41: 1002 | C41: nonsense | D41: (absent) | E41: on / attn 50 / act - | F41: (absent) | G41: off / attn 50 / act - | H41: =IF(AND(EXACT(D41,E41),EXACT(E41,F41),EXACT(F41,G41)),"Same","DIFF") -> DIFF
A42: DEFAULT | B42: 2000 | C42: Test | D42: (absent) | E42: (absent) | F42: on / attn 50 / act - | G42: (absent) | H42: =IF(AND(EXACT(D42,E42),EXACT(E42,F42),EXACT(F42,G42)),"Same","DIFF") -> DIFF
A43: DEFAULT | B43: 2001 | C43: test 1 | D43: (absent) | E43: (absent) | F43: on / attn 50 / act 5 | G43: (absent) | H43: =IF(AND(EXACT(D43,E43),EXACT(E43,F43),EXACT(F43,G43)),"Same","DIFF") -> DIFF
A44: DEFAULT | B44: 2005 | C44: Test Case | D44: (absent) | E44: (absent) | F44: on / attn 50 / act - | G44: (absent) | H44: =IF(AND(EXACT(D44,E44),EXACT(E44,F44),EXACT(F44,G44)),"Same","DIFF") -> DIFF
A45: DEFAULT | B45: 2500 | C45: Test Case 25 | D45: (absent) | E45: (absent) | F45: on / attn 50 / act - | G45: (absent) | H45: =IF(AND(EXACT(D45,E45),EXACT(E45,F45),EXACT(F45,G45)),"Same","DIFF") -> DIFF
A46: DEFAULT | B46: 3001 | C46: test123 | D46: (absent) | E46: (absent) | F46: on / attn 50 / act - | G46: (absent) | H46: =IF(AND(EXACT(D46,E46),EXACT(E46,F46),EXACT(F46,G46)),"Same","DIFF") -> DIFF
A47: CONTRACTORS | B47: 10 | D47: (absent) | E47: (absent) | F47: (absent) | G47: on / attn 1 / act 600 | H47: =IF(AND(EXACT(D47,E47),EXACT(E47,F47),EXACT(F47,G47)),"Same","DIFF") -> DIFF
A48: CONTRACTORS | B48: 30 | D48: off / attn 10 / act 10 | E48: off / attn 10 / act 10 | F48: off / attn 10 / act 10 | G48: off / attn 10 / act 10 | H48: =IF(AND(EXACT(D48,E48),EXACT(E48,F48),EXACT(F48,G48)),"Same","DIFF") -> Same
A49: CONTRACTORS | B49: 40 | D49: off / attn 50 / act - | E49: off / attn 50 / act - | F49: off / attn 50 / act - | G49: off / attn 50 / act - | H49: =IF(AND(EXACT(D49,E49),EXACT(E49,F49),EXACT(F49,G49)),"Same","DIFF") -> Same
A50: CONTRACTORS | B50: 50 | D50: on / attn 10 / act 0 | E50: on / attn 10 / act 0 | F50: on / attn 10 / act 0 | G50: on / attn 10 / act 0 | H50: =IF(AND(EXACT(D50,E50),EXACT(E50,F50),EXACT(F50,G50)),"Same","DIFF") -> Same
A51: CONTRACTORS | B51: 60 | D51: off / attn 50 / act 0 | E51: off / attn 50 / act 0 | F51: off / attn 50 / act 0 | G51: off / attn 50 / act 0 | H51: =IF(AND(EXACT(D51,E51),EXACT(E51,F51),EXACT(F51,G51)),"Same","DIFF") -> Same
A52: CONTRACTORS | B52: 70 | D52: off / attn 50 / act - | E52: off / attn 50 / act - | F52: off / attn 50 / act - | G52: off / attn 50 / act - | H52: =IF(AND(EXACT(D52,E52),EXACT(E52,F52),EXACT(F52,G52)),"Same","DIFF") -> Same
A53: CONTRACTORS | B53: 80 | D53: off / attn 1 / act - | E53: off / attn 1 / act - | F53: off / attn 1 / act - | G53: off / attn 1 / act - | H53: =IF(AND(EXACT(D53,E53),EXACT(E53,F53),EXACT(F53,G53)),"Same","DIFF") -> Same
A54: CONTRACTORS | B54: 130 | D54: on / attn 10 / act 600 | E54: on / attn 10 / act 600 | F54: on / attn 10 / act 600 | G54: on / attn 10 / act 600 | H54: =IF(AND(EXACT(D54,E54),EXACT(E54,F54),EXACT(F54,G54)),"Same","DIFF") -> Same
A55: CONTRACTORS | B55: 140 | D55: off / attn 10 / act - | E55: off / attn 10 / act - | F55: off / attn 10 / act - | G55: off / attn 10 / act - | H55: =IF(AND(EXACT(D55,E55),EXACT(E55,F55),EXACT(F55,G55)),"Same","DIFF") -> Same
A56: CONTRACTORS | B56: 150 | D56: off / attn 1 / act - | E56: off / attn 1 / act - | F56: off / attn 1 / act - | G56: off / attn 1 / act - | H56: =IF(AND(EXACT(D56,E56),EXACT(E56,F56),EXACT(F56,G56)),"Same","DIFF") -> Same
A57: CONTRACTORS | B57: 170 | D57: off / attn 50 / act - | E57: off / attn 50 / act - | F57: off / attn 50 / act - | G57: off / attn 50 / act - | H57: =IF(AND(EXACT(D57,E57),EXACT(E57,F57),EXACT(F57,G57)),"Same","DIFF") -> Same
A58: CONTRACTORS | B58: 260 | D58: off / attn 10 / act 21600 | E58: off / attn 10 / act 21600 | F58: off / attn 10 / act 21600 | G58: off / attn 10 / act 21600 | H58: =IF(AND(EXACT(D58,E58),EXACT(E58,F58),EXACT(F58,G58)),"Same","DIFF") -> Same
... A76: CONTRACTORS | B76: 450 | D76: (absent) | E76: (absent) | F76: off / attn 50 / act - | G76: (absent) | H76: =IF(AND(EXACT(D76,E76),EXACT(E76,F76),EXACT(F76,G76)),"Same","DIFF") -> DIFF
A77: CONTRACTORS | B77: 1000 | C77: Tasks Committed outside of a Shift | D77: on / attn 0 / act 1 | E77: on / attn 0 / act 1 | F77: on / attn 0 / act 1 | G77: on / attn 0 / act 1 | H77: =IF(AND(EXACT(D77,E77),EXACT(E77,F77),EXACT(F77,G77)),"Same","DIFF") -> Same
A78: CommittedActivitiesProfile | B78: 10 | D78: (absent) | E78: (absent) | F78: (absent) | G78: on / attn 1 / act 600 | H78: =IF(AND(EXACT(D78,E78),EXACT(E78,F78),EXACT(F78,G78)),"Same","DIFF") -> DIFF
A79: CommittedActivitiesProfile | B79: 20 | D79: (absent) | E79: (absent) | F79: (absent) | G79: on / attn 10 / act 10 | H79: =IF(AND(EXACT(D79,E79),EXACT(E79,F79),EXACT(F79,G79)),"Same","DIFF") -> DIFF
A80: CommittedActivitiesProfile | B80: 30 | D80: (absent) | E80: (absent) | F80: (absent) | G80: off / attn 10 / act 10 | H80: =IF(AND(EXACT(D80,E80),EXACT(E80,F80),EXACT(F80,G80)),"Same","DIFF") -> DIFF
A81: CommittedActivitiesProfile | B81: 40 | D81: (absent) | E81: (absent) | F81: (absent) | G81: off / attn 50 / act - | H81: =IF(AND(EXACT(D81,E81),EXACT(E81,F81),EXACT(F81,G81)),"Same","DIFF") -> DIFF
...

Sheet Group Permissions
A1: Group | B1: Permission | C1: Note | D1: PROD (allow/edit) | E1: ACC (UAT) (allow/edit) | F1: STG (allow/edit) | G1: TST (allow/edit) | H1: Status
A2: Administrator | B2: AdminSupportView | D2: (absent) | E2: T / T | F2: T / T | G2: T / T | H2: =IF(AND(EXACT(D2,E2),EXACT(E2,F2),EXACT(F2,G2)),"Same","DIFF") -> DIFF
A3: Administrator | B3: AdministrationWorkspace | D3: T / F | E3: T / F | F3: T / F | G3: T / F | H3: =IF(AND(EXACT(D3,E3),EXACT(E3,F3),EXACT(F3,G3)),"Same","DIFF") -> Same
A4: Administrator | B4: Administrator | D4: T / F | E4: T / F | F4: T / F | G4: T / F | H4: =IF(AND(EXACT(D4,E4),EXACT(E4,F4),EXACT(F4,G4)),"Same","DIFF") -> Same
A5: Administrator | B5: Assist | D5: (absent) | E5: T / T | F5: T / T | G5: T / T | H5: =IF(AND(EXACT(D5,E5),EXACT(E5,F5),EXACT(F5,G5)),"Same","DIFF") -> DIFF
A6: Administrator | B6: DataCaptureARCClearPersonalDataView | D6: T / F | E6: T / F | F6: T / F | G6: T / F | H6: =IF(AND(EXACT(D6,E6),EXACT(E6,F6),EXACT(F6,G6)),"Same","DIFF") -> Same
A7: Administrator | B7: DataCaptureView | D7: T / F | E7: T / F | F7: T / F | G7: T / F | H7: =IF(AND(EXACT(D7,E7),EXACT(E7,F7),EXACT(F7,G7)),"Same","DIFF") -> Same
A8: Administrator | B8: FilterResourceActivityBased | D8: (absent) | E8: T / T | F8: T / T | G8: T / T | H8: =IF(AND(EXACT(D8,E8),EXACT(E8,F8),EXACT(F8,G8)),"Same","DIFF") -> DIFF
A9: Administrator | B9: GatewayQuerySystemData | D9: T / F | E9: T / F | F9: T / F | G9: T / F | H9: =IF(AND(EXACT(D9,E9),EXACT(E9,F9),EXACT(F9,G9)),"Same","DIFF") -> Same
A10: Administrator | B10: GatewaySubmitData | D10: T / F | E10: T / F | F10: T / F | G10: T / F | H10: =IF(AND(EXACT(D10,E10),EXACT(E10,F10),EXACT(F10,G10)),"Same","DIFF") -> Same
A11: Administrator | B11: GatewaySubmitSystemData | D11: T / F | E11: T / F | F11: T / F | G11: T / F | H11: =IF(AND(EXACT(D11,E11),EXACT(E11,F11),EXACT(F11,G11)),"Same","DIFF") -> Same
A12: Administrator | B12: GatewaySystemManagement | D12: T / F | E12: T / F | F12: T / F | G12: T / F | H12: =IF(AND(EXACT(D12,E12),EXACT(E12,F12),EXACT(F12,G12)),"Same","DIFF") -> Same
A13: Administrator | B13: History | D13: T / F | E13: T / F | F13: T / F | G13: T / F | H13: =IF(AND(EXACT(D13,E13),EXACT(E13,F13),EXACT(F13,G13)),"Same","DIFF") -> Same
... A244: ST_Dispatch | B244: ViewAllResources | D244: (absent) | E244: (absent) | F244: (absent) | G244: T / T | H244: =IF(AND(EXACT(D244,E244),EXACT(E244,F244),EXACT(F244,G244)),"Same","DIFF") -> DIFF
A245: ST_Ops_Mgr | B245: ActInfoMemo | C245: spelling differs across envs | D245: (absent) | E245: F / T | F245: (absent) | G245: (absent) | H245: =IF(AND(EXACT(D245,E245),EXACT(E245,F245),EXACT(F245,G245)),"Same","DIFF") -> DIFF
A246: ST_Ops_Mgr | B246: ActInfoParts | C246: spelling differs across envs | D246: (absent) | E246: F / T | F246: (absent) | G246: (absent) | H246: =IF(AND(EXACT(D246,E246),EXACT(E246,F246),EXACT(F246,G246)),"Same","DIFF") -> DIFF
A247: ST_Ops_Mgr | B247: AdminEventsView | C247: spelling differs across envs | D247: F / T | E247: F / T | F247: F / T | G247: F / T | H247: =IF(AND(EXACT(D247,E247),EXACT(E247,F247),EXACT(F247,G247)),"Same","DIFF") -> Same
A248: ST_Ops_Mgr | B248: Assist | C248: spelling differs across envs | D248: (absent) | E248: F / T | F248: (absent) | G248: (absent) | H248: =IF(AND(EXACT(D248,E248),EXACT(E248,F248),EXACT(F248,G248)),"Same","DIFF") -> DIFF
A249: ST_Ops_Mgr | B249: ChildScreenResource | C249: spelling differs across envs | D249: T / T | E249: (absent) | F249: (absent) | G249: (absent) | H249: =IF(AND(EXACT(D249,E249),EXACT(E249,F249),EXACT(F249,G249)),"Same","DIFF") -> DIFF
A250: ST_Ops_Mgr | B250: CompareView | C250: spelling differs across envs | D250: F / T | E250: F / T | F250: F / T | G250: F / T | H250: =IF(AND(EXACT(D250,E250),EXACT(E250,F250),EXACT(F250,G250)),"Same","DIFF") -> Same
A251: ST_Ops_Mgr | B251: ExplanationsView | C251: spelling differs across envs | D251: F / T | E251: F / T | F251: F / T | G251: F / T | H251: =IF(AND(EXACT(D251,E251),EXACT(E251,F251),EXACT(F251,G251)),"Same","DIFF") -> Same
A252: ST_Ops_Mgr | B252: FilterResourceActivityBased | C252: spelling differs across envs | D252: T / T | E252: T / T | F252: T / T | G252: T / T | H252: =IF(AND(EXACT(D252,E252),EXACT(E252,F252),EXACT(F252,G252)),"Same","DIFF") -> Same
A253: ST_Ops_Mgr | B253: FilterShowFullAllocationDetails | C253: spelling differs across envs | D253: (absent) | E253: T / T | F253: (absent) | G253: (absent) | H253: =IF(AND(EXACT(D253,E253),EXACT(E253,F253),EXACT(F253,G253)),"Same","DIFF") -> DIFF
A254: ST_Ops_Mgr | B254: Gateway | C254: spelling differs across envs | D254: T / T | E254: (absent) | F254: (absent) | G254: F / T | H254: =IF(AND(EXACT(D254,E254),EXACT(E254,F254),EXACT(F254,G254)),"Same","DIFF") -> DIFF
A255: ST_Ops_Mgr | B255: GatewayQueryData | C255: spelling differs across envs | D255: F / T | E255: F / T | F255: F / T | G255: F / T | H255: =IF(AND(EXACT(D255,E255),EXACT(E255,F255),EXACT(F255,G255)),"Same","DIFF") -> Same
A256: ST_Ops_Mgr | B256: GatewaySubmitData | C256: spelling differs across envs | D256: F / T | E256: F / T | F256: F / T | G256: F / T | H256: =IF(AND(EXACT(D256,E256),EXACT(E256,F256),EXACT(F256,G256)),"Same","DIFF") -> Same
... A282: ST_Ops_Mgr | B282: ViewAllObjectGroups | C282: spelling differs across envs | D282: T / T | E282: T / T | F282: (absent) | G282: T / T | H282: =IF(AND(EXACT(D282,E282),EXACT(E282,F282),EXACT(F282,G282)),"Same","DIFF") -> DIFF
A283: ST_Planner | B283: ActInfoMemo | D283: (absent) | E283: F / T | F283: (absent) | G283: (absent) | H283: =IF(AND(EXACT(D283,E283),EXACT(E283,F283),EXACT(F283,G283)),"Same","DIFF") -> DIFF
A284: ST_Planner | B284: ActInfoParts | D284: (absent) | E284: F / T | F284: (absent) | G284: (absent) | H284: =IF(AND(EXACT(D284,E284),EXACT(E284,F284),EXACT(F284,G284)),"Same","DIFF") -> DIFF
A285: ST_Planner | B285: AdminEventsView | D285: F / T | E285: F / T | F285: F / T | G285: F / T | H285: =IF(AND(EXACT(D285,E285),EXACT(E285,F285),EXACT(F285,G285)),"Same","DIFF") -> Same
A286: ST_Planner | B286: AdminEventsViewServerEvents | D286: (absent) | E286: F / T | F286: (absent) | G286: (absent) | H286: =IF(AND(EXACT(D286,E286),EXACT(E286,F286),EXACT(F286,G286)),"Same","DIFF") -> DIFF
A287: ST_Planner | B287: AppointmentTempView | D287: F / T | E287: F / T | F287: (absent) | G287: (absent) | H287: =IF(AND(EXACT(D287,E287),EXACT(E287,F287),EXACT(F287,G287)),"Same","DIFF") -> DIFF
A288: ST_Planner | B288: Assist | D288: T / T | E288: T / T | F288: T / T | G288: T / T | H288: =IF(AND(EXACT(D288,E288),EXACT(E288,F288),EXACT(F288,G288)),"Same","DIFF") -> Same
A289: ST_Planner | B289: FilterResourceActivityBased | D289: T / T | E289: T / T | F289: T / T | G289: T / T | H289: =IF(AND(EXACT(D289,E289),EXACT(E289,F289),EXACT(F289,G289)),"Same","DIFF") -> Same
A290: ST_Planner | B290: Gateway | D290: (absent) | E290: (absent) | F290: T / T | G290: T / T | H290: =IF(AND(EXACT(D290,E290),EXACT(E290,F290),EXACT(F290,G290)),"Same","DIFF") -> DIFF
A291: ST_Planner | B291: GatewayQueryData | D291: F / T | E291: F / T | F291: F / T | G291: F / T | H291: =IF(AND(EXACT(D291,E291),EXACT(E291,F291),EXACT(F291,G291)),"Same","DIFF") -> Same
A292: ST_Planner | B292: GatewaySubmitData | D292: F / T | E292: F / T | F292: F / T | G292: F / T | H292: =IF(AND(EXACT(D292,E292),EXACT(E292,F292),EXACT(F292,G292)),"Same","DIFF") -> Same
A293: ST_Planner | B293: GatewaySystemManagement | D293: F / T | E293: F / T | F293: F / T | G293: F / T | H293: =IF(AND(EXACT(D293,E293),EXACT(E293,F293),EXACT(F293,G293)),"Same","DIFF") -> Same
A294: ST_Planner | B294: History | D294: T / T | E294: T / T | F294: T / T | G294: T / T | H294: =IF(AND(EXACT(D294,E294),EXACT(E294,F294),EXACT(F294,G294)),"Same","DIFF") -> Same
... A479: ST_WFM_MGR | B479: ViewAllObjectGroups | D479: T / T | E479: T / T | F479: (absent) | G479: T / T | H479: =IF(AND(EXACT(D479,E479),EXACT(E479,F479),EXACT(F479,G479)),"Same","DIFF") -> DIFF

Sheet Groups
A1: Group | B1: Attribute | D1: PROD | E1: ACC (UAT) | F1: STG | G1: TST | H1: Status
A2: 59a0f13b182240c9c3b013122ed5a6bf | B2: Present as | D2: (absent) | E2: (absent) | F2: (absent) | G2: 59a0f13b182240c9c3b013122ed5a6bf | H2: =IF(AND(EXACT(D2,E2),EXACT(E2,F2),EXACT(F2,G2)),"Same","DIFF") -> DIFF
A3: 59a0f13b182240c9c3b013122ed5a6bf | B3: Parent group | D3: (absent) | E3: (absent) | F3: (absent) | G3: (null) | H3: =IF(AND(EXACT(D3,E3),EXACT(E3,F3),EXACT(F3,G3)),"Same","DIFF") -> DIFF
A4: 59a0f13b182240c9c3b013122ed5a6bf | B4: Description | D4: (absent) | E4: (absent) | F4: (absent) | G4: (null) | H4: =IF(AND(EXACT(D4,E4),EXACT(E4,F4),EXACT(F4,G4)),"Same","DIFF") -> DIFF
A5: 59a0f13b182240c9c3b013122ed5a6bf | B5: Permission rows, allow + deny (count) | D5: =COUNTIFS('Group Permissions'!$A$2:$A$479,$A5,'Group Permissions'!D$2:D$479,"<>(absent)") -> 0 | E5: =COUNTIFS('Group Permissions'!$A$2:$A$479,$A5,'Group Permissions'!E$2:E$479,"<>(absent)") -> 0 | F5: =COUNTIFS('Group Permissions'!$A$2:$A$479,$A5,'Group Permissions'!F$2:F$479,"<>(absent)") -> 0 | G5: =COUNTIFS('Group Permissions'!$A$2:$A$479,$A5,'Group Permissions'!G$2:G$479,"<>(absent)") -> 0 | H5: =IF(AND(EXACT(D5,E5),EXACT(E5,F5),EXACT(F5,G5)),"Same","DIFF") -> Same
A6: Administrator | B6: Present as | D6: Administrator | E6: Administrator | F6: Administrator | G6: Administrator | H6: =IF(AND(EXACT(D6,E6),EXACT(E6,F6),EXACT(F6,G6)),"Same","DIFF") -> Same
A7: Administrator | B7: Parent group | D7: (null) | E7: (null) | F7: (null) | G7: (null) | H7: =IF(AND(EXACT(D7,E7),EXACT(E7,F7),EXACT(F7,G7)),"Same","DIFF") -> Same
A8: Administrator | B8: Description | D8: Grants admin access permissions to user | E8: Grants admin access permissions to user | F8: Grants admin access permissions to user | G8: Grants admin access permissions to user | H8: =IF(AND(EXACT(D8,E8),EXACT(E8,F8),EXACT(F8,G8)),"Same","DIFF") -> Same
A9: Administrator | B9: Permission rows, allow + deny (count) | D9: =COUNTIFS('Group Permissions'!$A$2:$A$479,$A9,'Group Permissions'!D$2:D$479,"<>(absent)") -> 13 | E9: =COUNTIFS('Group Permissions'!$A$2:$A$479,$A9,'Group Permissions'!E$2:E$479,"<>(absent)") -> 31 | F9: =COUNTIFS('Group Permissions'!$A$2:$A$479,$A9,'Group Permissions'!F$2:F$479,"<>(absent)") -> 31 | G9: =COUNTIFS('Group Permissions'!$A$2:$A$479,$A9,'Group Permissions'!G$2:G$479,"<>(absent)") -> 31 | H9: =IF(AND(EXACT(D9,E9),EXACT(E9,F9),EXACT(F9,G9)),"Same","DIFF") -> DIFF
A10: FNDSCH_ADMIN | B10: Present as | D10: FNDSCH_ADMIN | E10: FNDSCH_ADMIN | F10: FNDSCH_ADMIN | G10: FNDSCH_ADMIN | H10: =IF(AND(EXACT(D10,E10),EXACT(E10,F10),EXACT(F10,G10)),"Same","DIFF") -> Same
A11: FNDSCH_ADMIN | B11: Parent group | D11: FNDSCH_RUNTIME | E11: FNDSCH_RUNTIME | F11: FNDSCH_RUNTIME | G11: FNDSCH_RUNTIME | H11: =IF(AND(EXACT(D11,E11),EXACT(E11,F11),EXACT(F11,G11)),"Same","DIFF") -> Same
A12: FNDSCH_ADMIN | B12: Description | D12: (null) | E12: (null) | F12: (null) | G12: (null) | H12: =IF(AND(EXACT(D12,E12),EXACT(E12,F12),EXACT(F12,G12)),"Same","DIFF") -> Same
A13: FNDSCH_ADMIN | B13: Permission rows, allow + deny (count) | D13: =COUNTIFS('Group Permissions'!$A$2:$A$479,$A13,'Group Permissions'!D$2:D$479,"<>(absent)") -> 7 | E13: =COUNTIFS('Group Permissions'!$A$2:$A$479,$A13,'Group Permissions'!E$2:E$479,"<>(absent)") -> 7 | F13: =COUNTIFS('Group Permissions'!$A$2:$A$479,$A13,'Group Permissions'!F$2:F$479,"<>(absent)") -> 7 | G13: =COUNTIFS('Group Permissions'!$A$2:$A$479,$A13,'Group Permissions'!G$2:G$479,"<>(absent)") -> 7 | H13: =IF(AND(EXACT(D13,E13),EXACT(E13,F13),EXACT(F13,G13)),"Same","DIFF") -> Same
A14: FNDSCH_RUNTIME | B14: Present as | D14: FNDSCH_RUNTIME | E14: FNDSCH_RUNTIME | F14: FNDSCH_RUNTIME | G14: FNDSCH_RUNTIME | H14: =IF(AND(EXACT(D14,E14),EXACT(E14,F14),EXACT(F14,G14)),"Same","DIFF") -> Same
A15: FNDSCH_RUNTIME | B15: Parent group | D15: (null) | E15: (null) | F15: (null) | G15: (null) | H15: =IF(AND(EXACT(D15,E15),EXACT(E15,F15),EXACT(F15,G15)),"Same","DIFF") -> Same
A16: FNDSCH_RUNTIME | B16: Description | D16: (null) | E16: (null) | F16: (null) | G16: (null) | H16: =IF(AND(EXACT(D16,E16),EXACT(E16,F16),EXACT(F16,G16)),"Same","DIFF") -> Same
A17: FNDSCH_RUNTIME | B17: Permission rows, allow + deny (count) | D17: =COUNTIFS('Group Permissions'!$A$2:$A$479,$A17,'Group Permissions'!D$2:D$479,"<>(absent)") -> 0 | E17: =COUNTIFS('Group Permissions'!$A$2:$A$479,$A17,'Group Permissions'!E$2:E$479,"<>(absent)") -> 1 | F17: =COUNTIFS('Group Permissions'!$A$2:$A$479,$A17,'Group Permissions'!F$2:F$479,"<>(absent)") -> 1 | G17: =COUNTIFS('Group Permissions'!$A$2:$A$479,$A17,'Group Permissions'!G$2:G$479,"<>(absent)") -> 1 | H17: =IF(AND(EXACT(D17,E17),EXACT(E17,F17),EXACT(F17,G17)),"Same","DIFF") -> DIFF
A18: GOGH_ADMIN_PERMISSION | B18: Present as | D18: (absent) | E18: GOGH_ADMIN_PERMISSION | F18: GOGH_ADMIN_PERMISSION | G18: GOGH_ADMIN_PERMISSION | H18: =IF(AND(EXACT(D18,E18),EXACT(E18,F18),EXACT(F18,G18)),"Same","DIFF") -> DIFF
A19: GOGH_ADMIN_PERMISSION | B19: Parent group | D19: (absent) | E19: FNDSCH_ADMIN | F19: FNDSCH_ADMIN | G19: FNDSCH_ADMIN | H19: =IF(AND(EXACT(D19,E19),EXACT(E19,F19),EXACT(F19,G19)),"Same","DIFF") -> DIFF
A20: GOGH_ADMIN_PERMISSION | B20: Description | D20: (absent) | E20: (null) | F20: (null) | G20: (null) | H20: =IF(AND(EXACT(D20,E20),EXACT(E20,F20),EXACT(F20,G20)),"Same","DIFF") -> DIFF
A21: GOGH_ADMIN_PERMISSION | B21: Permission rows, allow + deny (count) | D21: =COUNTIFS('Group Permissions'!$A$2:$A$479,$A21,'Group Permissions'!D$2:D$479,"<>(absent)") -> 0 | E21: =COUNTIFS('Group Permissions'!$A$2:$A$479,$A21,'Group Permissions'!E$2:E$479,"<>(absent)") -> 0 | F21: =COUNTIFS('Group Permissions'!$A$2:$A$479,$A21,'Group Permissions'!F$2:F$479,"<>(absent)") -> 0 | G21: =COUNTIFS('Group Permissions'!$A$2:$A$479,$A21,'Group Permissions'!G$2:G$479,"<>(absent)") -> 0 | H21: =IF(AND(EXACT(D21,E21),EXACT(E21,F21),EXACT(F21,G21)),"Same","DIFF") -> Same
A22: GOGHSUPERUSER | B22: Present as | D22: (absent) | E22: GOGHSUPERUSER | F22: GOGHSUPERUSER | G22: (absent) | H22: =IF(AND(EXACT(D22,E22),EXACT(E22,F22),EXACT(F22,G22)),"Same","DIFF") -> DIFF
A23: GOGHSUPERUSER | B23: Parent group | D23: (absent) | E23: FNDSCH_ADMIN | F23: FNDSCH_ADMIN | G23: (absent) | H23: =IF(AND(EXACT(D23,E23),EXACT(E23,F23),EXACT(F23,G23)),"Same","DIFF") -> DIFF
A24: GOGHSUPERUSER | B24: Description | D24: (absent) | E24: (null) | F24: (null) | G24: (absent) | H24: =IF(AND(EXACT(D24,E24),EXACT(E24,F24),EXACT(F24,G24)),"Same","DIFF") -> DIFF
A25: GOGHSUPERUSER | B25: Permission rows, allow + deny (count) | D25: =COUNTIFS('Group Permissions'!$A$2:$A$479,$A25,'Group Permissions'!D$2:D$479,"<>(absent)") -> 0 | E25: =COUNTIFS('Group Permissions'!$A$2:$A$479,$A25,'Group Permissions'!E$2:E$479,"<>(absent)") -> 0 | F25: =COUNTIFS('Group Permissions'!$A$2:$A$479,$A25,'Group Permissions'!F$2:F$479,"<>(absent)") -> 1 | G25: =COUNTIFS('Group Permissions'!$A$2:$A$479,$A25,'Group Permissions'!G$2:G$479,"<>(absent)") -> 0 | H25: =IF(AND(EXACT(D25,E25),EXACT(E25,F25),EXACT(F25,G25)),"Same","DIFF") -> DIFF
A26: Integration | B26: Present as | D26: Integration | E26: Integration | F26: Integration | G26: Integration | H26: =IF(AND(EXACT(D26,E26),EXACT(E26,F26),EXACT(F26,G26)),"Same","DIFF") -> Same
A27: Integration | B27: Parent group | D27: (null) | E27: (null) | F27: (null) | G27: (null) | H27: =IF(AND(EXACT(D27,E27),EXACT(E27,F27),EXACT(F27,G27)),"Same","DIFF") -> Same
A28: Integration | B28: Description | D28: Integration Permissions | E28: Integration Permissions | F28: Integration Permissions | G28: Integration Permissions | H28: =IF(AND(EXACT(D28,E28),EXACT(E28,F28),EXACT(F28,G28)),"Same","DIFF") -> Same
A29: Integration | B29: Permission rows, allow + deny (count) | D29: =COUNTIFS('Group Permissions'!$A$2:$A$479,$A29,'Group Permissions'!D$2:D$479,"<>(absent)") -> 6 | E29: =COUNTIFS('Group Permissions'!$A$2:$A$479,$A29,'Group Permissions'!E$2:E$479,"<>(absent)") -> 10 | F29: =COUNTIFS('Group Permissions'!$A$2:$A$479,$A29,'Group Permissions'!F$2:F$479,"<>(absent)") -> 10 | G29: =COUNTIFS('Group Permissions'!$A$2:$A$479,$A29,'Group Permissions'!G$2:G$479,"<>(absent)") -> 10 | H29: =IF(AND(EXACT(D29,E29),EXACT(E29,F29),EXACT(F29,G29)),"Same","DIFF") -> DIFF
A30: IntegrationUsers | B30: Present as | D30: IntegrationUsers | E30: IntegrationUsers | F30: IntegrationUsers | G30: IntegrationUsers | H30: =IF(AND(EXACT(D30,E30),EXACT(E30,F30),EXACT(F30,G30)),"Same","DIFF") -> Same
A31: IntegrationUsers | B31: Parent group | D31: (null) | E31: (null) | F31: (null) | G31: (null) | H31: =IF(AND(EXACT(D31,E31),EXACT(E31,F31),EXACT(F31,G31)),"Same","DIFF") -> Same
A32: IntegrationUsers | B32: Description | D32: Integration users with access to the Scheduling Gateway | E32: Integration users with access to the Scheduling Gateway | F32: Integration users with access to the Scheduling Gateway | G32: Integration users with access to the Scheduling Gateway | H32: =IF(AND(EXACT(D32,E32),EXACT(E32,F32),EXACT(F32,G32)),"Same","DIFF") -> Same
A33: IntegrationUsers | B33: Permission rows, allow + deny (count) | D33: =COUNTIFS('Group Permissions'!$A$2:$A$479,$A33,'Group Permissions'!D$2:D$479,"<>(absent)") -> 4 | E33: =COUNTIFS('Group Permissions'!$A$2:$A$479,$A33,'Group Permissions'!E$2:E$479,"<>(absent)") -> 4 | F33: =COUNTIFS('Group Permissions'!$A$2:$A$479,$A33,'Group Permissions'!F$2:F$479,"<>(absent)") -> 4 | G33: =COUNTIFS('Group Permissions'!$A$2:$A$479,$A33,'Group Permissions'!G$2:G$479,"<>(absent)") -> 4 | H33: =IF(AND(EXACT(D33,E33),EXACT(E33,F33),EXACT(F33,G33)),"Same","DIFF") -> Same
A34: ItineraryOnly | B34: Present as | D34: ItineraryOnly | E34: ItineraryOnly | F34: ItineraryOnly | G34: ItineraryOnly | H34: =IF(AND(EXACT(D34,E34),EXACT(E34,F34),EXACT(F34,G34)),"Same","DIFF") -> Same
A35: ItineraryOnly | B35: Parent group | D35: (null) | E35: (null) | F35: (null) | G35: (null) | H35: =IF(AND(EXACT(D35,E35),EXACT(E35,F35),EXACT(F35,G35)),"Same","DIFF") -> Same
A36: ItineraryOnly | B36: Description | D36: Resource user with access restricted to the Itinerary view only | E36: Resource user with access restricted to the Itinerary view only | F36: Resource user with access restricted to the Itinerary view only | G36: Resource user with access restricted to the Itinerary view only | H36: =IF(AND(EXACT(D36,E36),EXACT(E36,F36),EXACT(F36,G36)),"Same","DIFF") -> Same
A37: ItineraryOnly | B37: Permission rows, allow + deny (count) | D37: =COUNTIFS('Group Permissions'!$A$2:$A$479,$A37,'Group Permissions'!D$2:D$479,"<>(absent)") -> 35 | E37: =COUNTIFS('Group Permissions'!$A$2:$A$479,$A37,'Group Permissions'!E$2:E$479,"<>(absent)") -> 35 | F37: =COUNTIFS('Group Permissions'!$A$2:$A$479,$A37,'Group Permissions'!F$2:F$479,"<>(absent)") -> 35 | G37: =COUNTIFS('Group Permissions'!$A$2:$A$479,$A37,'Group Permissions'!G$2:G$479,"<>(absent)") -> 35 | H37: =IF(AND(EXACT(D37,E37),EXACT(E37,F37),EXACT(F37,G37)),"Same","DIFF") -> Same
A38: NORTH | B38: Present as | D38: NORTH | E38: NORTH | F38: NORTH | G38: NORTH | H38: =IF(AND(EXACT(D38,E38),EXACT(E38,F38),EXACT(F38,G38)),"Same","DIFF") -> Same
A39: NORTH | B39: Parent group | D39: (null) | E39: Administrator | F39: Administrator | G39: Administrator | H39: =IF(AND(EXACT(D39,E39),EXACT(E39,F39),EXACT(F39,G39)),"Same","DIFF") -> DIFF
A40: NORTH | B40: Description | D40: North␣ | E40: North Site | F40: North Site | G40: North Site | H40: =IF(AND(EXACT(D40,E40),EXACT(E40,F40),EXACT(F40,G40)),"Same","DIFF") -> DIFF
...

Sheet Org Permissions
A1: Permission | D1: PROD (allow/edit) | E1: ACC (UAT) (allow/edit) | F1: STG (allow/edit) | G1: TST (allow/edit) | H1: Status
A2: AdminSubOrganisationsView | D2: F / F | E2: F / F | F2: F / F | G2: F / F | H2: =IF(AND(EXACT(D2,E2),EXACT(E2,F2),EXACT(F2,G2)),"Same","DIFF") -> Same
A3: AdminSystemDiagramView | D3: F / F | E3: F / F | F3: F / F | G3: F / F | H3: =IF(AND(EXACT(D3,E3),EXACT(E3,F3),EXACT(F3,G3)),"Same","DIFF") -> Same
A4: AdminSystemView | D4: F / F | E4: F / F | F4: F / F | G4: F / F | H4: =IF(AND(EXACT(D4,E4),EXACT(E4,F4),EXACT(F4,G4)),"Same","DIFF") -> Same
A5: AdministrationWorkspace | D5: (absent) | E5: (absent) | F5: T / T | G5: (absent) | H5: =IF(AND(EXACT(D5,E5),EXACT(E5,F5),EXACT(F5,G5)),"Same","DIFF") -> DIFF
A6: Administrator | D6: (absent) | E6: (absent) | F6: (absent) | G6: T / T | H6: =IF(AND(EXACT(D6,E6),EXACT(E6,F6),EXACT(F6,G6)),"Same","DIFF") -> DIFF
A7: DataCaptureView | D7: (absent) | E7: (absent) | F7: T / T | G7: (absent) | H7: =IF(AND(EXACT(D7,E7),EXACT(E7,F7),EXACT(F7,G7)),"Same","DIFF") -> DIFF
A8: GatewayAllowURLCredentials | D8: (absent) | E8: (absent) | F8: (absent) | G8: F / T | H8: =IF(AND(EXACT(D8,E8),EXACT(E8,F8),EXACT(F8,G8)),"Same","DIFF") -> DIFF
A9: GatewayBasicHttpAuthentication | D9: (absent) | E9: (absent) | F9: (absent) | G9: F / T | H9: =IF(AND(EXACT(D9,E9),EXACT(E9,F9),EXACT(F9,G9)),"Same","DIFF") -> DIFF
A10: GatewayOpenIdAllowStandardAuthentication | D10: (absent) | E10: (absent) | F10: (absent) | G10: F / T | H10: =IF(AND(EXACT(D10,E10),EXACT(E10,F10),EXACT(F10,G10)),"Same","DIFF") -> DIFF
A11: ViewAllDatasets | D11: T / T | E11: F / T | F11: T / T | G11: (absent) | H11: =IF(AND(EXACT(D11,E11),EXACT(E11,F11),EXACT(F11,G11)),"Same","DIFF") -> DIFF
A12: ViewAllEvents | D12: F / F | E12: F / F | F12: F / F | G12: F / F | H12: =IF(AND(EXACT(D12,E12),EXACT(E12,F12),EXACT(F12,G12)),"Same","DIFF") -> Same
A13: ViewAllObjectGroups | D13: T / T | E13: (absent) | F13: (absent) | G13: (absent) | H13: =IF(AND(EXACT(D13,E13),EXACT(E13,F13),EXACT(F13,G13)),"Same","DIFF") -> DIFF

Sheet Lists
A1: Org-default list | B1: Position | D1: PROD | E1: ACC (UAT) | F1: STG | G1: TST | H1: Status
A2: List type 5 | B2: 1 | D2: Activity ID | E2: Activity ID | F2: Activity ID | G2: Activity ID | H2: =IF(AND(EXACT(D2,E2),EXACT(E2,F2),EXACT(F2,G2)),"Same","DIFF") -> Same
A3: List type 5 | B3: 2 | D3: Call ID | E3: Call ID | F3: Call ID | G3: Call ID | H3: =IF(AND(EXACT(D3,E3),EXACT(E3,F3),EXACT(F3,G3)),"Same","DIFF") -> Same
A4: List type 5 | B4: 3 | D4: Street | E4: Street | F4: Street | G4: Service ID | H4: =IF(AND(EXACT(D4,E4),EXACT(E4,F4),EXACT(F4,G4)),"Same","DIFF") -> DIFF
A5: List type 5 | B5: 4 | D5: Address | E5: Address | F5: Address | G5: Siebel Order Number | H5: =IF(AND(EXACT(D5,E5),EXACT(E5,F5),EXACT(F5,G5)),"Same","DIFF") -> DIFF
A6: List type 5 | B6: 5 | D6: City | E6: City | F6: City | G6: Job ID | H6: =IF(AND(EXACT(D6,E6),EXACT(E6,F6),EXACT(F6,G6)),"Same","DIFF") -> DIFF
A7: List type 5 | B7: 6 | D7: GB | E7: GB | F7: GB | G7: OOS | H7: =IF(AND(EXACT(D7,E7),EXACT(E7,F7),EXACT(F7,G7)),"Same","DIFF") -> DIFF
A8: List type 5 | B8: 7 | D8: Customer Name | E8: Customer Name | F8: Customer Name | G8: Hotspot Type | H8: =IF(AND(EXACT(D8,E8),EXACT(E8,F8),EXACT(F8,G8)),"Same","DIFF") -> DIFF
A9: List type 5 | B9: 8 | D9: Service ID | E9: Service ID | F9: Service ID | G9: (null) | H9: =IF(AND(EXACT(D9,E9),EXACT(E9,F9),EXACT(F9,G9)),"Same","DIFF") -> DIFF
A10: List type 5 | B10: 9 | D10: Siebel Order Number | E10: Siebel Order Number | F10: Siebel Order Number | G10: (null) | H10: =IF(AND(EXACT(D10,E10),EXACT(E10,F10),EXACT(F10,G10)),"Same","DIFF") -> DIFF
A11: List type 5 | B11: 10 | D11: Job ID | E11: Job ID | F11: Job ID | G11: (null) | H11: =IF(AND(EXACT(D11,E11),EXACT(E11,F11),EXACT(F11,G11)),"Same","DIFF") -> DIFF
A12: List type 5 | B12: 11 | D12: OOS | E12: OOS | F12: OOS | G12: (null) | H12: =IF(AND(EXACT(D12,E12),EXACT(E12,F12),EXACT(F12,G12)),"Same","DIFF") -> DIFF
